Internal Server Error: /api/users/register/
Traceback (most recent call last):
  File "C:\Python313\Lib\site-packages\django\core\handlers\exception.py", line 55, in inner
    response = get_response(request)
  File "C:\Python313\Lib\site-packages\django\core\handlers\base.py", line 197, in _get_response
    response = wrapped_callback(request, *callback_args, **callback_kwargs)
  File "C:\Python313\Lib\site-packages\django\views\decorators\csrf.py", line 56, in wrapper_view
    return view_func(*args, **kwargs)
  File "C:\Python313\Lib\site-packages\django\views\generic\base.py", line 104, in view
    return self.dispatch(request, *args, **kwargs)
           ~~~~~~~~~~~~~^^^^^^^^^^^^^^^^^^^^^^^^^^
  File "C:\Python313\Lib\site-packages\rest_framework\views.py", line 515, in dispatch
    response = self.handle_exception(exc)
  File "C:\Python313\Lib\site-packages\rest_framework\views.py", line 475, in handle_exception
    self.raise_uncaught_exception(exc)
    ~~~~~~~~~~~~~~~~~~~~~~~~~~~~~^^^^^
  File "C:\Python313\Lib\site-packages\rest_framework\views.py", line 486, in raise_uncaught_exception
    raise exc
  File "C:\Python313\Lib\site-packages\rest_framework\views.py", line 512, in dispatch
    response = handler(request, *args, **kwargs)
  File "C:\Users\DELL\Desktop\IBMS\Thies-Jobs\backend\users\views.py", line 37, in post
    user = serializer.save()
  File "C:\Python313\Lib\site-packages\rest_framework\serializers.py", line 210, in save
    self.instance = self.create(validated_data)
                    ~~~~~~~~~~~^^^^^^^^^^^^^^^^
  File "C:\Users\DELL\Desktop\IBMS\Thies-Jobs\backend\users\serializers.py", line 32, in create
    if User.objects.filter(pseudo=validated_data['pseudo']).exists():
                                  ~~~~~~~~~~~~~~^^^^^^^^^^
KeyError: 'pseudo'
"POST /api/users/register/ HTTP/1.1" 500 103402
Internal Server Error: /api/users/register/
Traceback (most recent call last):
  File "C:\Python313\Lib\site-packages\django\core\handlers\exception.py", line 55, in inner
    response = get_response(request)
  File "C:\Python313\Lib\site-packages\django\core\handlers\base.py", line 197, in _get_response
    response = wrapped_callback(request, *callback_args, **callback_kwargs)
  File "C:\Python313\Lib\site-packages\django\views\decorators\csrf.py", line 56, in wrapper_view
    return view_func(*args, **kwargs)
  File "C:\Python313\Lib\site-packages\django\views\generic\base.py", line 104, in view
    return self.dispatch(request, *args, **kwargs)
           ~~~~~~~~~~~~~^^^^^^^^^^^^^^^^^^^^^^^^^^
  File "C:\Python313\Lib\site-packages\rest_framework\views.py", line 515, in dispatch
    response = self.handle_exception(exc)
  File "C:\Python313\Lib\site-packages\rest_framework\views.py", line 475, in handle_exception
    self.raise_uncaught_exception(exc)
    ~~~~~~~~~~~~~~~~~~~~~~~~~~~~~^^^^^
  File "C:\Python313\Lib\site-packages\rest_framework\views.py", line 486, in raise_uncaught_exception
    raise exc
  File "C:\Python313\Lib\site-packages\rest_framework\views.py", line 512, in dispatch
    response = handler(request, *args, **kwargs)
  File "C:\Users\DELL\Desktop\IBMS\Thies-Jobs\backend\users\views.py", line 37, in post
    user = serializer.save()
  File "C:\Python313\Lib\site-packages\rest_framework\serializers.py", line 210, in save
    self.instance = self.create(validated_data)
                    ~~~~~~~~~~~^^^^^^^^^^^^^^^^
  File "C:\Users\DELL\Desktop\IBMS\Thies-Jobs\backend\users\serializers.py", line 35, in create
    full_name=validated_data['full_name'],
              ~~~~~~~~~~~~~~^^^^^^^^^^^^^
KeyError: 'full_name'
"POST /api/users/register/ HTTP/1.1" 500 103424
Internal Server Error: /api/users/updateProfileUser/1
Traceback (most recent call last):
  File "C:\Python313\Lib\site-packages\django\core\handlers\exception.py", line 55, in inner
    response = get_response(request)
  File "C:\Python313\Lib\site-packages\django\utils\deprecation.py", line 136, in __call__
    response = self.process_response(request, response)
  File "C:\Python313\Lib\site-packages\django\middleware\common.py", line 108, in process_response
    return self.response_redirect_class(self.get_full_path_with_slash(request))
                                        ~~~~~~~~~~~~~~~~~~~~~~~~~~~~~^^^^^^^^^
  File "C:\Python313\Lib\site-packages\django\middleware\common.py", line 87, in get_full_path_with_slash
    raise RuntimeError(
    ...<9 lines>...
    )
RuntimeError: You called this URL via PATCH, but the URL doesn't end in a slash and you have APPEND_SLASH set. Django can't redirect to the slash URL while maintaining PATCH data. Change your form to point to 127.0.0.1:8000/api/users/updateProfileUser/1/ (note the trailing slash), or set APPEND_SLASH=False in your Django settings.
"PATCH /api/users/updateProfileUser/1 HTTP/1.1" 500 69520
Internal Server Error: /api/users/updateProfileUser/2
Traceback (most recent call last):
  File "C:\Python313\Lib\site-packages\django\core\handlers\exception.py", line 55, in inner
    response = get_response(request)
  File "C:\Python313\Lib\site-packages\django\utils\deprecation.py", line 136, in __call__
    response = self.process_response(request, response)
  File "C:\Python313\Lib\site-packages\django\middleware\common.py", line 108, in process_response
    return self.response_redirect_class(self.get_full_path_with_slash(request))
                                        ~~~~~~~~~~~~~~~~~~~~~~~~~~~~~^^^^^^^^^
  File "C:\Python313\Lib\site-packages\django\middleware\common.py", line 87, in get_full_path_with_slash
    raise RuntimeError(
    ...<9 lines>...
    )
RuntimeError: You called this URL via PATCH, but the URL doesn't end in a slash and you have APPEND_SLASH set. Django can't redirect to the slash URL while maintaining PATCH data. Change your form to point to 127.0.0.1:8000/api/users/updateProfileUser/2/ (note the trailing slash), or set APPEND_SLASH=False in your Django settings.
"PATCH /api/users/updateProfileUser/2 HTTP/1.1" 500 69520
Internal Server Error: /api/users/updateProfileUser/2
Traceback (most recent call last):
  File "C:\Python313\Lib\site-packages\django\core\handlers\exception.py", line 55, in inner
    response = get_response(request)
  File "C:\Python313\Lib\site-packages\django\utils\deprecation.py", line 136, in __call__
    response = self.process_response(request, response)
  File "C:\Python313\Lib\site-packages\django\middleware\common.py", line 108, in process_response
    return self.response_redirect_class(self.get_full_path_with_slash(request))
                                        ~~~~~~~~~~~~~~~~~~~~~~~~~~~~~^^^^^^^^^
  File "C:\Python313\Lib\site-packages\django\middleware\common.py", line 87, in get_full_path_with_slash
    raise RuntimeError(
    ...<9 lines>...
    )
RuntimeError: You called this URL via PUT, but the URL doesn't end in a slash and you have APPEND_SLASH set. Django can't redirect to the slash URL while maintaining PUT data. Change your form to point to 127.0.0.1:8000/api/users/updateProfileUser/2/ (note the trailing slash), or set APPEND_SLASH=False in your Django settings.
"PUT /api/users/updateProfileUser/2 HTTP/1.1" 500 69490
Internal Server Error: /api/users/updateProfileUser/2
Traceback (most recent call last):
  File "C:\Python313\Lib\site-packages\django\core\handlers\exception.py", line 55, in inner
    response = get_response(request)
  File "C:\Python313\Lib\site-packages\django\utils\deprecation.py", line 136, in __call__
    response = self.process_response(request, response)
  File "C:\Python313\Lib\site-packages\django\middleware\common.py", line 108, in process_response
    return self.response_redirect_class(self.get_full_path_with_slash(request))
                                        ~~~~~~~~~~~~~~~~~~~~~~~~~~~~~^^^^^^^^^
  File "C:\Python313\Lib\site-packages\django\middleware\common.py", line 87, in get_full_path_with_slash
    raise RuntimeError(
    ...<9 lines>...
    )
RuntimeError: You called this URL via PUT, but the URL doesn't end in a slash and you have APPEND_SLASH set. Django can't redirect to the slash URL while maintaining PUT data. Change your form to point to 127.0.0.1:8000/api/users/updateProfileUser/2/ (note the trailing slash), or set APPEND_SLASH=False in your Django settings.
"PUT /api/users/updateProfileUser/2 HTTP/1.1" 500 69490
Internal Server Error: /api/users/updateProfileUser/1
Traceback (most recent call last):
  File "C:\Python313\Lib\site-packages\django\core\handlers\exception.py", line 55, in inner
    response = get_response(request)
  File "C:\Python313\Lib\site-packages\django\utils\deprecation.py", line 136, in __call__
    response = self.process_response(request, response)
  File "C:\Python313\Lib\site-packages\django\middleware\common.py", line 108, in process_response
    return self.response_redirect_class(self.get_full_path_with_slash(request))
                                        ~~~~~~~~~~~~~~~~~~~~~~~~~~~~~^^^^^^^^^
  File "C:\Python313\Lib\site-packages\django\middleware\common.py", line 87, in get_full_path_with_slash
    raise RuntimeError(
    ...<9 lines>...
    )
RuntimeError: You called this URL via PUT, but the URL doesn't end in a slash and you have APPEND_SLASH set. Django can't redirect to the slash URL while maintaining PUT data. Change your form to point to 127.0.0.1:8000/api/users/updateProfileUser/1/ (note the trailing slash), or set APPEND_SLASH=False in your Django settings.
"PUT /api/users/updateProfileUser/1 HTTP/1.1" 500 69490
Invalid HTTP_HOST header: 'localhost:8000'. You may need to add 'localhost' to ALLOWED_HOSTS.
Traceback (most recent call last):
  File "C:\Python313\Lib\site-packages\django\core\handlers\exception.py", line 55, in inner
    response = get_response(request)
  File "C:\Python313\Lib\site-packages\django\utils\deprecation.py", line 133, in __call__
    response = self.process_request(request)
  File "C:\Python313\Lib\site-packages\django\middleware\common.py", line 48, in process_request
    host = request.get_host()
  File "C:\Python313\Lib\site-packages\django\http\request.py", line 167, in get_host
    raise DisallowedHost(msg)
django.core.exceptions.DisallowedHost: Invalid HTTP_HOST header: 'localhost:8000'. You may need to add 'localhost' to ALLOWED_HOSTS.
Invalid HTTP_HOST header: 'localhost:8000'. You may need to add 'localhost' to ALLOWED_HOSTS.
Traceback (most recent call last):
  File "C:\Python313\Lib\site-packages\django\core\handlers\exception.py", line 55, in inner
    response = get_response(request)
  File "C:\Python313\Lib\site-packages\django\utils\deprecation.py", line 133, in __call__
    response = self.process_request(request)
  File "C:\Python313\Lib\site-packages\django\middleware\common.py", line 48, in process_request
    host = request.get_host()
  File "C:\Python313\Lib\site-packages\django\http\request.py", line 167, in get_host
    raise DisallowedHost(msg)
django.core.exceptions.DisallowedHost: Invalid HTTP_HOST header: 'localhost:8000'. You may need to add 'localhost' to ALLOWED_HOSTS.
